<?xml version="1.0"?>
<robot xmlns:xacro="http://www.ros.org/wiki/xacro" name="h2017" >

  <xacro:arg name="color"   default="blue"/>

  <xacro:property name="cr" value="$(arg color)"/>

  <xacro:property name="M_PI" value="3.14159"/>
  
  <xacro:if value="${cr == 'white'}">
     <xacro:include filename="$(find dootion_description)/urdf/macro.h2017.white.xacro" />
  </xacro:if>
  <xacro:if value="${cr == 'blue'}">
     <xacro:include filename="$(find dootion_description)/urdf/macro.h2017.blue.xacro" />
  </xacro:if>
  <xacro:h2017/>

  <link name="base_link">
    <visual>
      <origin xyz="0 0 0" rpy="0 0 0" />
      <geometry>
        <mesh filename="package://dootion_description/meshes/vention_base/column_base.dae"/>
        <!-- <mesh filename="package://dootion_description/meshes/vention_base/column_base_wheeled.dae"/> -->
      </geometry>
      <!-- <material name="grey"/> -->
    </visual>
    <collision>
      <origin xyz="0 0 0" rpy="0 0 0" />
      <geometry>
        <mesh filename="package://dootion_description/meshes/vention_base/column_base.dae"/>
        <!-- <mesh filename="package://dootion_description/meshes/vention_base/column_base_wheeled.dae"/> -->
      </geometry>
      <!-- <material name="grey"/> -->
    </collision>
  </link>

  <link name="base_elevator">
    <visual>
      <geometry>
        <mesh filename="package://dootion_description/meshes/vention_base/column_platform.dae" />
      </geometry>
      <collision>
        <mesh filename="package://dootion_description/meshes/vention_base/column_platform.dae" />
      </collision>
      <origin xyz="0 0 0" rpy="0 0 0"/>
      <!-- <material name="grey"/> -->
    </visual>
    <collision>
      <geometry>
        <mesh filename="package://dootion_description/meshes/vention_base/column_platform.dae" />
      </geometry>
      <collision>
        <mesh filename="package://dootion_description/meshes/vention_base/column_platform.dae" />
      </collision>
      <origin xyz="0 0 0" rpy="0 0 0"/>
      <!-- <material name="grey"/> -->
    </collision>
  </link>

  <joint name="tower_prismatic" type="prismatic">
    <parent link="base_link"/>
    <child link="base_elevator"/>
    <limit effort="10000.0" lower="0" upper="0.8" velocity="0.5"/>
    <origin xyz="0 0 0" rpy="0 0 0"/>
    <axis xyz="0 0 1"/>
    <dynamics damping="1.0" friction="0.1"/>
  </joint>

  <joint name="arm_mount" type="fixed">
    <origin xyz="0 0 0.83" rpy="0 0 0"/>
    <parent link="base_elevator"/>
    <child link="base_0"/>
  </joint>

  <!-- <link name="end_effector_tip">
    <visual>
      <origin xyz="0 0 0" rpy="0 0 0" />
    </visual>
  </link>

  <joint name="end_effector_tip_joint" type="fixed">
    <origin xyz="0 0 0.15" rpy="${M_PI/2} 0 0"/>
    <parent link="link6"/>
    <child link="end_effector_tip"/>
  </joint> -->

  <!-- <xacro:include filename="$(find ouster_description)/urdf/OS1-64.urdf.xacro" />
  <xacro:OS1-64 parent="link6"> -->
    <!-- <origin xyz="0 0 1" rpy="0 ${M_PI/6} 0" /> -->
    <!-- <origin xyz="0 0 .4" rpy="0 0 0" />
  </xacro:OS1-64> -->

</robot>
